Modules Release 4.8.0 (2021-07-14)
DCC-SW: Added modules (2021-nov/XeonE5-2660v3)
DCC-SW: Removed standard modules: /apps/dcc/etc/ModulesSL73/modulefiles
DCC-SW: Using gnu/11.2.0 compiler
DCC-SW: Released modules (2021-nov/XeonE5-2660v3)
DCC-SW: Added modules (2020-aug/XeonE5-2660v3)
DCC-SW: Removed standard modules: /apps/dcc/etc/ModulesSL73/modulefiles
DCC-SW: Using gnu/9.3.0 compiler
rank=00 L00: Traceback (most recent call last):
rank=00 L01:   File "calc_of_dos_1.py", line 7, in <module>
rank=00 L02:     slab, calc = restart('top.gpw')
rank=00 L03:   File "/zhome/06/4/136859/dft_venv/gpaw/gpaw/__init__.py", line 211, in restart
rank=00 L04:     calc = Class(filename, **kwargs)
rank=00 L05:   File "/zhome/06/4/136859/dft_venv/gpaw/gpaw/__init__.py", line 207, in GPAW
rank=00 L06:     return OldGPAW(*args, **kwargs)
rank=00 L07:   File "/zhome/06/4/136859/dft_venv/gpaw/gpaw/calculator.py", line 168, in __init__
rank=00 L08:     Calculator.__init__(self, restart, label=label, **kwargs)
rank=00 L09:   File "/zhome/06/4/136859/dft_venv/ase/ase/calculators/calculator.py", line 605, in __init__
rank=00 L10:     self.read(restart)  # read parameters, atoms and results
rank=00 L11:   File "/zhome/06/4/136859/dft_venv/gpaw/gpaw/calculator.py", line 304, in read
rank=00 L12:     self.reader = reader = Reader(filename)
rank=00 L13:   File "/zhome/06/4/136859/dft_venv/gpaw/gpaw/io/__init__.py", line 4, in Reader
rank=00 L14:     return ulm.Reader(filename)
rank=00 L15:   File "/zhome/06/4/136859/dft_venv/ase/ase/io/ulm.py", line 476, in __init__
rank=00 L16:     fd = Path(fd).open('rb')
rank=00 L17:   File "/dtu/sw/dcc/SL73/2020-aug/XeonE5-2660v3/gnu/9.3.0/python/3.8.5/lib/python3.8/pathlib.py", line 1218, in open
rank=00 L18:     return io.open(self, mode, buffering, encoding, errors, newline,
rank=00 L19:   File "/dtu/sw/dcc/SL73/2020-aug/XeonE5-2660v3/gnu/9.3.0/python/3.8.5/lib/python3.8/pathlib.py", line 1074, in _opener
rank=00 L20:     return self._accessor.open(self, flags, mode)
rank=00 L21: FileNotFoundError: [Errno 2] No such file or directory: 'top.gpw'
GPAW CLEANUP (node 0): <class 'FileNotFoundError'> occurred.  Calling MPI_Abort!
rank=05 L00: Traceback (most recent call last):
rank=05 L01:   File "calc_of_dos_1.py", line 7, in <module>
rank=05 L02:     slab, calc = restart('top.gpw')
rank=05 L03:   File "/zhome/06/4/136859/dft_venv/gpaw/gpaw/__init__.py", line 211, in restart
rank=05 L04:     calc = Class(filename, **kwargs)
rank=05 L05:   File "/zhome/06/4/136859/dft_venv/gpaw/gpaw/__init__.py", line 207, in GPAW
rank=05 L06:     return OldGPAW(*args, **kwargs)
rank=05 L07:   File "/zhome/06/4/136859/dft_venv/gpaw/gpaw/calculator.py", line 168, in __init__
rank=05 L08:     Calculator.__init__(self, restart, label=label, **kwargs)
rank=05 L09:   File "/zhome/06/4/136859/dft_venv/ase/ase/calculators/calculator.py", line 605, in __init__
rank=05 L10:     self.read(restart)  # read parameters, atoms and results
rank=05 L11:   File "/zhome/06/4/136859/dft_venv/gpaw/gpaw/calculator.py", line 304, in read
rank=05 L12:     self.reader = reader = Reader(filename)
rank=05 L13:   File "/zhome/06/4/136859/dft_venv/gpaw/gpaw/io/__init__.py", line 4, in Reader
rank=05 L14:     return ulm.Reader(filename)
rank=05 L15:   File "/zhome/06/4/136859/dft_venv/ase/ase/io/ulm.py", line 476, in __init__
rank=05 L16:     fd = Path(fd).open('rb')
rank=05 L17:   File "/dtu/sw/dcc/SL73/2020-aug/XeonE5-2660v3/gnu/9.3.0/python/3.8.5/lib/python3.8/pathlib.py", line 1218, in open
rank=05 L18:     return io.open(self, mode, buffering, encoding, errors, newline,
rank=05 L19:   File "/dtu/sw/dcc/SL73/2020-aug/XeonE5-2660v3/gnu/9.3.0/python/3.8.5/lib/python3.8/pathlib.py", line 1074, in _opener
rank=05 L20:     return self._accessor.open(self, flags, mode)
rank=05 L21: FileNotFoundError: [Errno 2] No such file or directory: 'top.gpw'
GPAW CLEANUP (node 5): <class 'FileNotFoundError'> occurred.  Calling MPI_Abort!
rank=02 L00: Traceback (most recent call last):
rank=02 L01:   File "calc_of_dos_1.py", line 7, in <module>
rank=02 L02:     slab, calc = restart('top.gpw')
rank=02 L03:   File "/zhome/06/4/136859/dft_venv/gpaw/gpaw/__init__.py", line 211, in restart
rank=02 L04:     calc = Class(filename, **kwargs)
rank=02 L05:   File "/zhome/06/4/136859/dft_venv/gpaw/gpaw/__init__.py", line 207, in GPAW
rank=02 L06:     return OldGPAW(*args, **kwargs)
rank=02 L07:   File "/zhome/06/4/136859/dft_venv/gpaw/gpaw/calculator.py", line 168, in __init__
rank=02 L08:     Calculator.__init__(self, restart, label=label, **kwargs)
rank=02 L09:   File "/zhome/06/4/136859/dft_venv/ase/ase/calculators/calculator.py", line 605, in __init__
rank=02 L10:     self.read(restart)  # read parameters, atoms and results
rank=02 L11:   File "/zhome/06/4/136859/dft_venv/gpaw/gpaw/calculator.py", line 304, in read
rank=02 L12:     self.reader = reader = Reader(filename)
rank=02 L13:   File "/zhome/06/4/136859/dft_venv/gpaw/gpaw/io/__init__.py", line 4, in Reader
rank=02 L14:     return ulm.Reader(filename)
rank=02 L15:   File "/zhome/06/4/136859/dft_venv/ase/ase/io/ulm.py", line 476, in __init__
rank=02 L16:     fd = Path(fd).open('rb')
rank=02 L17:   File "/dtu/sw/dcc/SL73/2020-aug/XeonE5-2660v3/gnu/9.3.0/python/3.8.5/lib/python3.8/pathlib.py", line 1218, in open
rank=02 L18:     return io.open(self, mode, buffering, encoding, errors, newline,
rank=02 L19:   File "/dtu/sw/dcc/SL73/2020-aug/XeonE5-2660v3/gnu/9.3.0/python/3.8.5/lib/python3.8/pathlib.py", line 1074, in _opener
rank=02 L20:     return self._accessor.open(self, flags, mode)
rank=02 L21: FileNotFoundError: [Errno 2] No such file or directory: 'top.gpw'
rank=06 L00: Traceback (most recent call last):
rank=06 L01:   File "calc_of_dos_1.py", line 7, in <module>
rank=06 L02:     slab, calc = restart('top.gpw')
rank=06 L03:   File "/zhome/06/4/136859/dft_venv/gpaw/gpaw/__init__.py", line 211, in restart
rank=06 L04:     calc = Class(filename, **kwargs)
rank=06 L05:   File "/zhome/06/4/136859/dft_venv/gpaw/gpaw/__init__.py", line 207, in GPAW
rank=06 L06:     return OldGPAW(*args, **kwargs)
rank=06 L07:   File "/zhome/06/4/136859/dft_venv/gpaw/gpaw/calculator.py", line 168, in __init__
rank=06 L08:     Calculator.__init__(self, restart, label=label, **kwargs)
rank=06 L09:   File "/zhome/06/4/136859/dft_venv/ase/ase/calculators/calculator.py", line 605, in __init__
rank=06 L10:     self.read(restart)  # read parameters, atoms and results
rank=06 L11:   File "/zhome/06/4/136859/dft_venv/gpaw/gpaw/calculator.py", line 304, in read
rank=06 L12:     self.reader = reader = Reader(filename)
rank=06 L13:   File "/zhome/06/4/136859/dft_venv/gpaw/gpaw/io/__init__.py", line 4, in Reader
rank=06 L14:     return ulm.Reader(filename)
rank=06 L15:   File "/zhome/06/4/136859/dft_venv/ase/ase/io/ulm.py", line 476, in __init__
rank=06 L16:     fd = Path(fd).open('rb')
rank=06 L17:   File "/dtu/sw/dcc/SL73/2020-aug/XeonE5-2660v3/gnu/9.3.0/python/3.8.5/lib/python3.8/pathlib.py", line 1218, in open
rank=06 L18:     return io.open(self, mode, buffering, encoding, errors, newline,
rank=06 L19:   File "/dtu/sw/dcc/SL73/2020-aug/XeonE5-2660v3/gnu/9.3.0/python/3.8.5/lib/python3.8/pathlib.py", line 1074, in _opener
rank=06 L20:     return self._accessor.open(self, flags, mode)
rank=06 L21: FileNotFoundError: [Errno 2] No such file or directory: 'top.gpw'
GPAW CLEANUP (node 6): <class 'FileNotFoundError'> occurred.  Calling MPI_Abort!
GPAW CLEANUP (node 2): <class 'FileNotFoundError'> occurred.  Calling MPI_Abort!
rank=07 L00: Traceback (most recent call last):
rank=07 L01:   File "calc_of_dos_1.py", line 7, in <module>
rank=07 L02:     slab, calc = restart('top.gpw')
rank=07 L03:   File "/zhome/06/4/136859/dft_venv/gpaw/gpaw/__init__.py", line 211, in restart
rank=07 L04:     calc = Class(filename, **kwargs)
rank=07 L05:   File "/zhome/06/4/136859/dft_venv/gpaw/gpaw/__init__.py", line 207, in GPAW
rank=07 L06:     return OldGPAW(*args, **kwargs)
rank=07 L07:   File "/zhome/06/4/136859/dft_venv/gpaw/gpaw/calculator.py", line 168, in __init__
rank=07 L08:     Calculator.__init__(self, restart, label=label, **kwargs)
rank=07 L09:   File "/zhome/06/4/136859/dft_venv/ase/ase/calculators/calculator.py", line 605, in __init__
rank=07 L10:     self.read(restart)  # read parameters, atoms and results
rank=07 L11:   File "/zhome/06/4/136859/dft_venv/gpaw/gpaw/calculator.py", line 304, in read
rank=07 L12:     self.reader = reader = Reader(filename)
rank=07 L13:   File "/zhome/06/4/136859/dft_venv/gpaw/gpaw/io/__init__.py", line 4, in Reader
rank=07 L14:     return ulm.Reader(filename)
rank=07 L15:   File "/zhome/06/4/136859/dft_venv/ase/ase/io/ulm.py", line 476, in __init__
rank=07 L16:     fd = Path(fd).open('rb')
rank=07 L17:   File "/dtu/sw/dcc/SL73/2020-aug/XeonE5-2660v3/gnu/9.3.0/python/3.8.5/lib/python3.8/pathlib.py", line 1218, in open
rank=07 L18:     return io.open(self, mode, buffering, encoding, errors, newline,
rank=07 L19:   File "/dtu/sw/dcc/SL73/2020-aug/XeonE5-2660v3/gnu/9.3.0/python/3.8.5/lib/python3.8/pathlib.py", line 1074, in _opener
rank=07 L20:     return self._accessor.open(self, flags, mode)
rank=07 L21: FileNotFoundError: [Errno 2] No such file or directory: 'top.gpw'
GPAW CLEANUP (node 7): <class 'FileNotFoundError'> occurred.  Calling MPI_Abort!
rank=04 L00: Traceback (most recent call last):
rank=04 L01:   File "calc_of_dos_1.py", line 7, in <module>
rank=04 L02:     slab, calc = restart('top.gpw')
rank=04 L03:   File "/zhome/06/4/136859/dft_venv/gpaw/gpaw/__init__.py", line 211, in restart
rank=04 L04:     calc = Class(filename, **kwargs)
rank=04 L05:   File "/zhome/06/4/136859/dft_venv/gpaw/gpaw/__init__.py", line 207, in GPAW
rank=04 L06:     return OldGPAW(*args, **kwargs)
rank=04 L07:   File "/zhome/06/4/136859/dft_venv/gpaw/gpaw/calculator.py", line 168, in __init__
rank=04 L08:     Calculator.__init__(self, restart, label=label, **kwargs)
rank=04 L09:   File "/zhome/06/4/136859/dft_venv/ase/ase/calculators/calculator.py", line 605, in __init__
rank=04 L10:     self.read(restart)  # read parameters, atoms and results
rank=04 L11:   File "/zhome/06/4/136859/dft_venv/gpaw/gpaw/calculator.py", line 304, in read
rank=04 L12:     self.reader = reader = Reader(filename)
rank=04 L13:   File "/zhome/06/4/136859/dft_venv/gpaw/gpaw/io/__init__.py", line 4, in Reader
rank=04 L14:     return ulm.Reader(filename)
rank=04 L15:   File "/zhome/06/4/136859/dft_venv/ase/ase/io/ulm.py", line 476, in __init__
rank=04 L16:     fd = Path(fd).open('rb')
rank=04 L17:   File "/dtu/sw/dcc/SL73/2020-aug/XeonE5-2660v3/gnu/9.3.0/python/3.8.5/lib/python3.8/pathlib.py", line 1218, in open
rank=04 L18:     return io.open(self, mode, buffering, encoding, errors, newline,
rank=04 L19:   File "/dtu/sw/dcc/SL73/2020-aug/XeonE5-2660v3/gnu/9.3.0/python/3.8.5/lib/python3.8/pathlib.py", line 1074, in _opener
rank=04 L20:     return self._accessor.open(self, flags, mode)
rank=04 L21: FileNotFoundError: [Errno 2] No such file or directory: 'top.gpw'
GPAW CLEANUP (node 4): <class 'FileNotFoundError'> occurred.  Calling MPI_Abort!
rank=08 L00: Traceback (most recent call last):
rank=08 L01:   File "calc_of_dos_1.py", line 7, in <module>
rank=08 L02:     slab, calc = restart('top.gpw')
rank=08 L03:   File "/zhome/06/4/136859/dft_venv/gpaw/gpaw/__init__.py", line 211, in restart
rank=08 L04:     calc = Class(filename, **kwargs)
rank=08 L05:   File "/zhome/06/4/136859/dft_venv/gpaw/gpaw/__init__.py", line 207, in GPAW
rank=08 L06:     return OldGPAW(*args, **kwargs)
rank=08 L07:   File "/zhome/06/4/136859/dft_venv/gpaw/gpaw/calculator.py", line 168, in __init__
rank=08 L08:     Calculator.__init__(self, restart, label=label, **kwargs)
rank=08 L09:   File "/zhome/06/4/136859/dft_venv/ase/ase/calculators/calculator.py", line 605, in __init__
rank=08 L10:     self.read(restart)  # read parameters, atoms and results
rank=08 L11:   File "/zhome/06/4/136859/dft_venv/gpaw/gpaw/calculator.py", line 304, in read
rank=08 L12:     self.reader = reader = Reader(filename)
rank=08 L13:   File "/zhome/06/4/136859/dft_venv/gpaw/gpaw/io/__init__.py", line 4, in Reader
rank=08 L14:     return ulm.Reader(filename)
rank=08 L15:   File "/zhome/06/4/136859/dft_venv/ase/ase/io/ulm.py", line 476, in __init__
rank=08 L16:     fd = Path(fd).open('rb')
rank=08 L17:   File "/dtu/sw/dcc/SL73/2020-aug/XeonE5-2660v3/gnu/9.3.0/python/3.8.5/lib/python3.8/pathlib.py", line 1218, in open
rank=08 L18:     return io.open(self, mode, buffering, encoding, errors, newline,
rank=08 L19:   File "/dtu/sw/dcc/SL73/2020-aug/XeonE5-2660v3/gnu/9.3.0/python/3.8.5/lib/python3.8/pathlib.py", line 1074, in _opener
rank=08 L20:     return self._accessor.open(self, flags, mode)
rank=08 L21: FileNotFoundError: [Errno 2] No such file or directory: 'top.gpw'
GPAW CLEANUP (node 8): <class 'FileNotFoundError'> occurred.  Calling MPI_Abort!
rank=01 L00: Traceback (most recent call last):
rank=01 L01:   File "calc_of_dos_1.py", line 7, in <module>
rank=01 L02:     slab, calc = restart('top.gpw')
rank=01 L03:   File "/zhome/06/4/136859/dft_venv/gpaw/gpaw/__init__.py", line 211, in restart
rank=01 L04:     calc = Class(filename, **kwargs)
rank=01 L05:   File "/zhome/06/4/136859/dft_venv/gpaw/gpaw/__init__.py", line 207, in GPAW
rank=01 L06:     return OldGPAW(*args, **kwargs)
rank=01 L07:   File "/zhome/06/4/136859/dft_venv/gpaw/gpaw/calculator.py", line 168, in __init__
rank=01 L08:     Calculator.__init__(self, restart, label=label, **kwargs)
rank=01 L09:   File "/zhome/06/4/136859/dft_venv/ase/ase/calculators/calculator.py", line 605, in __init__
rank=01 L10:     self.read(restart)  # read parameters, atoms and results
rank=01 L11:   File "/zhome/06/4/136859/dft_venv/gpaw/gpaw/calculator.py", line 304, in read
rank=01 L12:     self.reader = reader = Reader(filename)
rank=01 L13:   File "/zhome/06/4/136859/dft_venv/gpaw/gpaw/io/__init__.py", line 4, in Reader
rank=01 L14:     return ulm.Reader(filename)
rank=01 L15:   File "/zhome/06/4/136859/dft_venv/ase/ase/io/ulm.py", line 476, in __init__
rank=01 L16:     fd = Path(fd).open('rb')
rank=01 L17:   File "/dtu/sw/dcc/SL73/2020-aug/XeonE5-2660v3/gnu/9.3.0/python/3.8.5/lib/python3.8/pathlib.py", line 1218, in open
rank=01 L18:     return io.open(self, mode, buffering, encoding, errors, newline,
rank=01 L19:   File "/dtu/sw/dcc/SL73/2020-aug/XeonE5-2660v3/gnu/9.3.0/python/3.8.5/lib/python3.8/pathlib.py", line 1074, in _opener
rank=01 L20:     return self._accessor.open(self, flags, mode)
rank=01 L21: FileNotFoundError: [Errno 2] No such file or directory: 'top.gpw'
GPAW CLEANUP (node 1): <class 'FileNotFoundError'> occurred.  Calling MPI_Abort!
rank=03 L00: Traceback (most recent call last):
rank=03 L01:   File "calc_of_dos_1.py", line 7, in <module>
rank=03 L02:     slab, calc = restart('top.gpw')
rank=03 L03:   File "/zhome/06/4/136859/dft_venv/gpaw/gpaw/__init__.py", line 211, in restart
rank=03 L04:     calc = Class(filename, **kwargs)
rank=03 L05:   File "/zhome/06/4/136859/dft_venv/gpaw/gpaw/__init__.py", line 207, in GPAW
rank=03 L06:     return OldGPAW(*args, **kwargs)
rank=03 L07:   File "/zhome/06/4/136859/dft_venv/gpaw/gpaw/calculator.py", line 168, in __init__
rank=03 L08:     Calculator.__init__(self, restart, label=label, **kwargs)
rank=03 L09:   File "/zhome/06/4/136859/dft_venv/ase/ase/calculators/calculator.py", line 605, in __init__
rank=03 L10:     self.read(restart)  # read parameters, atoms and results
rank=03 L11:   File "/zhome/06/4/136859/dft_venv/gpaw/gpaw/calculator.py", line 304, in read
rank=03 L12:     self.reader = reader = Reader(filename)
rank=03 L13:   File "/zhome/06/4/136859/dft_venv/gpaw/gpaw/io/__init__.py", line 4, in Reader
rank=03 L14:     return ulm.Reader(filename)
rank=03 L15:   File "/zhome/06/4/136859/dft_venv/ase/ase/io/ulm.py", line 476, in __init__
rank=03 L16:     fd = Path(fd).open('rb')
rank=03 L17:   File "/dtu/sw/dcc/SL73/2020-aug/XeonE5-2660v3/gnu/9.3.0/python/3.8.5/lib/python3.8/pathlib.py", line 1218, in open
rank=03 L18:     return io.open(self, mode, buffering, encoding, errors, newline,
rank=03 L19:   File "/dtu/sw/dcc/SL73/2020-aug/XeonE5-2660v3/gnu/9.3.0/python/3.8.5/lib/python3.8/pathlib.py", line 1074, in _opener
rank=03 L20:     return self._accessor.open(self, flags, mode)
rank=03 L21: FileNotFoundError: [Errno 2] No such file or directory: 'top.gpw'
GPAW CLEANUP (node 3): <class 'FileNotFoundError'> occurred.  Calling MPI_Abort!
rank=09 L00: Traceback (most recent call last):
rank=09 L01:   File "calc_of_dos_1.py", line 7, in <module>
rank=09 L02:     slab, calc = restart('top.gpw')
rank=09 L03:   File "/zhome/06/4/136859/dft_venv/gpaw/gpaw/__init__.py", line 211, in restart
rank=09 L04:     calc = Class(filename, **kwargs)
rank=09 L05:   File "/zhome/06/4/136859/dft_venv/gpaw/gpaw/__init__.py", line 207, in GPAW
rank=09 L06:     return OldGPAW(*args, **kwargs)
rank=09 L07:   File "/zhome/06/4/136859/dft_venv/gpaw/gpaw/calculator.py", line 168, in __init__
rank=09 L08:     Calculator.__init__(self, restart, label=label, **kwargs)
rank=09 L09:   File "/zhome/06/4/136859/dft_venv/ase/ase/calculators/calculator.py", line 605, in __init__
rank=09 L10:     self.read(restart)  # read parameters, atoms and results
rank=09 L11:   File "/zhome/06/4/136859/dft_venv/gpaw/gpaw/calculator.py", line 304, in read
rank=09 L12:     self.reader = reader = Reader(filename)
rank=09 L13:   File "/zhome/06/4/136859/dft_venv/gpaw/gpaw/io/__init__.py", line 4, in Reader
rank=09 L14:     return ulm.Reader(filename)
rank=09 L15:   File "/zhome/06/4/136859/dft_venv/ase/ase/io/ulm.py", line 476, in __init__
rank=09 L16:     fd = Path(fd).open('rb')
rank=09 L17:   File "/dtu/sw/dcc/SL73/2020-aug/XeonE5-2660v3/gnu/9.3.0/python/3.8.5/lib/python3.8/pathlib.py", line 1218, in open
rank=09 L18:     return io.open(self, mode, buffering, encoding, errors, newline,
rank=09 L19:   File "/dtu/sw/dcc/SL73/2020-aug/XeonE5-2660v3/gnu/9.3.0/python/3.8.5/lib/python3.8/pathlib.py", line 1074, in _opener
rank=09 L20:     return self._accessor.open(self, flags, mode)
rank=09 L21: FileNotFoundError: [Errno 2] No such file or directory: 'top.gpw'
GPAW CLEANUP (node 9): <class 'FileNotFoundError'> occurred.  Calling MPI_Abort!
rank=10 L00: Traceback (most recent call last):
rank=10 L01:   File "calc_of_dos_1.py", line 7, in <module>
rank=10 L02:     slab, calc = restart('top.gpw')
rank=10 L03:   File "/zhome/06/4/136859/dft_venv/gpaw/gpaw/__init__.py", line 211, in restart
rank=10 L04:     calc = Class(filename, **kwargs)
rank=10 L05:   File "/zhome/06/4/136859/dft_venv/gpaw/gpaw/__init__.py", line 207, in GPAW
rank=10 L06:     return OldGPAW(*args, **kwargs)
rank=10 L07:   File "/zhome/06/4/136859/dft_venv/gpaw/gpaw/calculator.py", line 168, in __init__
rank=10 L08:     Calculator.__init__(self, restart, label=label, **kwargs)
rank=10 L09:   File "/zhome/06/4/136859/dft_venv/ase/ase/calculators/calculator.py", line 605, in __init__
rank=10 L10:     self.read(restart)  # read parameters, atoms and results
rank=10 L11:   File "/zhome/06/4/136859/dft_venv/gpaw/gpaw/calculator.py", line 304, in read
rank=10 L12:     self.reader = reader = Reader(filename)
rank=10 L13:   File "/zhome/06/4/136859/dft_venv/gpaw/gpaw/io/__init__.py", line 4, in Reader
rank=10 L14:     return ulm.Reader(filename)
rank=10 L15:   File "/zhome/06/4/136859/dft_venv/ase/ase/io/ulm.py", line 476, in __init__
rank=10 L16:     fd = Path(fd).open('rb')
rank=10 L17:   File "/dtu/sw/dcc/SL73/2020-aug/XeonE5-2660v3/gnu/9.3.0/python/3.8.5/lib/python3.8/pathlib.py", line 1218, in open
rank=10 L18:     return io.open(self, mode, buffering, encoding, errors, newline,
rank=10 L19:   File "/dtu/sw/dcc/SL73/2020-aug/XeonE5-2660v3/gnu/9.3.0/python/3.8.5/lib/python3.8/pathlib.py", line 1074, in _opener
rank=10 L20:     return self._accessor.open(self, flags, mode)
rank=10 L21: FileNotFoundError: [Errno 2] No such file or directory: 'top.gpw'
GPAW CLEANUP (node 10): <class 'FileNotFoundError'> occurred.  Calling MPI_Abort!
rank=11 L00: Traceback (most recent call last):
rank=11 L01:   File "calc_of_dos_1.py", line 7, in <module>
rank=11 L02:     slab, calc = restart('top.gpw')
rank=11 L03:   File "/zhome/06/4/136859/dft_venv/gpaw/gpaw/__init__.py", line 211, in restart
rank=11 L04:     calc = Class(filename, **kwargs)
rank=11 L05:   File "/zhome/06/4/136859/dft_venv/gpaw/gpaw/__init__.py", line 207, in GPAW
rank=11 L06:     return OldGPAW(*args, **kwargs)
rank=11 L07:   File "/zhome/06/4/136859/dft_venv/gpaw/gpaw/calculator.py", line 168, in __init__
rank=11 L08:     Calculator.__init__(self, restart, label=label, **kwargs)
rank=11 L09:   File "/zhome/06/4/136859/dft_venv/ase/ase/calculators/calculator.py", line 605, in __init__
rank=11 L10:     self.read(restart)  # read parameters, atoms and results
rank=11 L11:   File "/zhome/06/4/136859/dft_venv/gpaw/gpaw/calculator.py", line 304, in read
rank=11 L12:     self.reader = reader = Reader(filename)
rank=11 L13:   File "/zhome/06/4/136859/dft_venv/gpaw/gpaw/io/__init__.py", line 4, in Reader
rank=11 L14:     return ulm.Reader(filename)
rank=11 L15:   File "/zhome/06/4/136859/dft_venv/ase/ase/io/ulm.py", line 476, in __init__
rank=11 L16:     fd = Path(fd).open('rb')
rank=11 L17:   File "/dtu/sw/dcc/SL73/2020-aug/XeonE5-2660v3/gnu/9.3.0/python/3.8.5/lib/python3.8/pathlib.py", line 1218, in open
rank=11 L18:     return io.open(self, mode, buffering, encoding, errors, newline,
rank=11 L19:   File "/dtu/sw/dcc/SL73/2020-aug/XeonE5-2660v3/gnu/9.3.0/python/3.8.5/lib/python3.8/pathlib.py", line 1074, in _opener
rank=11 L20:     return self._accessor.open(self, flags, mode)
rank=11 L21: FileNotFoundError: [Errno 2] No such file or directory: 'top.gpw'
GPAW CLEANUP (node 11): <class 'FileNotFoundError'> occurred.  Calling MPI_Abort!
--------------------------------------------------------------------------
MPI_ABORT was invoked on rank 0 in communicator MPI_COMM_WORLD
with errorcode 42.

NOTE: invoking MPI_ABORT causes Open MPI to kill all MPI processes.
You may or may not see output from other processes, depending on
exactly when Open MPI kills them.
--------------------------------------------------------------------------
[n-62-29-17:03900] PMIX ERROR: UNREACHABLE in file ../../../../../../../opal/mca/pmix/pmix3x/pmix/src/server/pmix_server.c at line 2193
[n-62-29-17:03900] PMIX ERROR: UNREACHABLE in file ../../../../../../../opal/mca/pmix/pmix3x/pmix/src/server/pmix_server.c at line 2193
[n-62-29-17:03900] PMIX ERROR: UNREACHABLE in file ../../../../../../../opal/mca/pmix/pmix3x/pmix/src/server/pmix_server.c at line 2193
[n-62-29-17:03900] PMIX ERROR: UNREACHABLE in file ../../../../../../../opal/mca/pmix/pmix3x/pmix/src/server/pmix_server.c at line 2193
[n-62-29-17:03900] PMIX ERROR: UNREACHABLE in file ../../../../../../../opal/mca/pmix/pmix3x/pmix/src/server/pmix_server.c at line 2193
[n-62-29-17:03900] PMIX ERROR: UNREACHABLE in file ../../../../../../../opal/mca/pmix/pmix3x/pmix/src/server/pmix_server.c at line 2193
[n-62-29-17:03900] PMIX ERROR: UNREACHABLE in file ../../../../../../../opal/mca/pmix/pmix3x/pmix/src/server/pmix_server.c at line 2193
[n-62-29-17:03900] PMIX ERROR: UNREACHABLE in file ../../../../../../../opal/mca/pmix/pmix3x/pmix/src/server/pmix_server.c at line 2193
[n-62-29-17:03900] PMIX ERROR: UNREACHABLE in file ../../../../../../../opal/mca/pmix/pmix3x/pmix/src/server/pmix_server.c at line 2193
[n-62-29-17:03900] PMIX ERROR: UNREACHABLE in file ../../../../../../../opal/mca/pmix/pmix3x/pmix/src/server/pmix_server.c at line 2193
[n-62-29-17:03900] PMIX ERROR: UNREACHABLE in file ../../../../../../../opal/mca/pmix/pmix3x/pmix/src/server/pmix_server.c at line 2193
[n-62-29-17:03900] 11 more processes have sent help message help-mpi-api.txt / mpi-abort
[n-62-29-17:03900] Set MCA parameter "orte_base_help_aggregate" to 0 to see all help / error messages
